Exception in Tkinter callbackTraceback (most recent call last):Traceback (most recent call last):Traceback (most recent call last):
Traceback (most recent call last):


During handling of the above exception, another exception occurred:



During handling of the above exception, another exception occurred:



During handling of the above exception, another exception occurred:



During handling of the above exception, another exception occurred:


